<?xml version="1.0" ?>
<!-- =================================================================================== -->
<!-- |    This document was autogenerated by xacro from /home/oedeh/physical-ai-jetson-robotics-lab/ros2_ws/src/rosmaster_m3pro_description/urdf/rosmaster_m3pro.urdf.xacro | -->
<!-- |    EDITING THIS FILE BY HAND IS NOT RECOMMENDED                                 | -->
<!-- =================================================================================== -->
<robot name="rosmaster_m3pro">
  <material name="m3pro_black">
    <color rgba="0.02 0.025 0.03 1.0"/>
  </material>
  <material name="m3pro_dark_gray">
    <color rgba="0.12 0.13 0.14 1.0"/>
  </material>
  <material name="m3pro_aluminum">
    <color rgba="0.62 0.64 0.62 1.0"/>
  </material>
  <material name="m3pro_green">
    <color rgba="0.05 0.45 0.22 1.0"/>
  </material>
  <material name="m3pro_blue">
    <color rgba="0.05 0.20 0.45 1.0"/>
  </material>
  <material name="m3pro_lidar">
    <color rgba="0.01 0.01 0.01 1.0"/>
  </material>
  <material name="m3pro_camera">
    <color rgba="0.03 0.035 0.04 1.0"/>
  </material>
  <link name="odom"/>
  <joint name="odom_to_base_footprint" type="fixed">
    <parent link="odom"/>
    <child link="base_footprint"/>
    <origin rpy="0 0 0" xyz="0 0 0"/>
  </joint>
  <link name="base_footprint"/>
  <link name="base_link">
    <visual>
      <origin rpy="0 0 0" xyz="0 0 0.0315"/>
      <geometry>
        <box size="0.36 0.3 0.0342"/>
      </geometry>
      <material name="m3pro_black"/>
    </visual>
    <visual>
      <origin rpy="0 0 0" xyz="0 0 0.0702"/>
      <geometry>
        <box size="0.31679999999999997 0.23399999999999999 0.0144"/>
      </geometry>
      <material name="m3pro_green"/>
    </visual>
    <visual>
      <origin rpy="0 0 0" xyz="0.0648 0 0.09179999999999999"/>
      <geometry>
        <box size="0.1152 0.165 0.018"/>
      </geometry>
      <material name="m3pro_dark_gray"/>
    </visual>
    <collision>
      <origin rpy="0 0 0" xyz="0 0 0.045"/>
      <geometry>
        <box size="0.36 0.3 0.09"/>
      </geometry>
    </collision>
    <inertial>
      <origin rpy="0 0 0" xyz="0 0 0.045"/>
      <mass value="5.5"/>
      <inertia ixx="0.044962499999999996" ixy="0.0" ixz="0.0" iyy="0.0631125" iyz="0.0" izz="0.10065"/>
    </inertial>
  </link>
  <joint name="base_footprint_joint" type="fixed">
    <parent link="base_footprint"/>
    <child link="base_link"/>
    <origin rpy="0 0 0" xyz="0 0 0.04"/>
  </joint>
  <link name="front_left_wheel_link">
    <visual>
      <origin rpy="1.5707963267948966 0 0" xyz="0 0 0"/>
      <geometry>
        <cylinder length="0.038" radius="0.04"/>
      </geometry>
      <material name="m3pro_black"/>
    </visual>
    <visual>
      <origin rpy="1.5707963267948966 0 0" xyz="0 0 0"/>
      <geometry>
        <cylinder length="0.041800000000000004" radius="0.018000000000000002"/>
      </geometry>
      <material name="m3pro_aluminum"/>
    </visual>
    <visual>
      <origin rpy="0.70 0 0.70" xyz="0 0 0"/>
      <geometry>
        <box size="0.043699999999999996 0.008 0.062000000000000006"/>
      </geometry>
      <material name="m3pro_dark_gray"/>
    </visual>
    <visual>
      <origin rpy="-0.70 0 -0.70" xyz="0 0 0"/>
      <geometry>
        <box size="0.043699999999999996 0.008 0.062000000000000006"/>
      </geometry>
      <material name="m3pro_dark_gray"/>
    </visual>
    <visual>
      <origin rpy="0.70 0 2.35" xyz="0 0 0"/>
      <geometry>
        <box size="0.043699999999999996 0.008 0.062000000000000006"/>
      </geometry>
      <material name="m3pro_dark_gray"/>
    </visual>
    <visual>
      <origin rpy="-0.70 0 -2.35" xyz="0 0 0"/>
      <geometry>
        <box size="0.043699999999999996 0.008 0.062000000000000006"/>
      </geometry>
      <material name="m3pro_dark_gray"/>
    </visual>
    <collision>
      <origin rpy="1.5707963267948966 0 0" xyz="0 0 0"/>
      <geometry>
        <cylinder length="0.038" radius="0.04"/>
      </geometry>
    </collision>
    <inertial>
      <origin rpy="1.5707963267948966 0 0" xyz="0 0 0"/>
      <mass value="0.35"/>
      <inertia ixx="0.00018211666666666663" ixy="0.0" ixz="0.0" iyy="0.00018211666666666663" iyz="0.0" izz="0.00028"/>
    </inertial>
  </link>
  <joint name="front_left_wheel_joint" type="continuous">
    <parent link="base_link"/>
    <child link="front_left_wheel_link"/>
    <origin rpy="0 0 0" xyz="0.145 0.13 -0.01"/>
    <axis xyz="0 1 0"/>
    <limit effort="20.0" velocity="20.0"/>
    <dynamics damping="0.05" friction="0.02"/>
  </joint>
  <link name="front_right_wheel_link">
    <visual>
      <origin rpy="1.5707963267948966 0 0" xyz="0 0 0"/>
      <geometry>
        <cylinder length="0.038" radius="0.04"/>
      </geometry>
      <material name="m3pro_black"/>
    </visual>
    <visual>
      <origin rpy="1.5707963267948966 0 0" xyz="0 0 0"/>
      <geometry>
        <cylinder length="0.041800000000000004" radius="0.018000000000000002"/>
      </geometry>
      <material name="m3pro_aluminum"/>
    </visual>
    <visual>
      <origin rpy="0.70 0 0.70" xyz="0 0 0"/>
      <geometry>
        <box size="0.043699999999999996 0.008 0.062000000000000006"/>
      </geometry>
      <material name="m3pro_dark_gray"/>
    </visual>
    <visual>
      <origin rpy="-0.70 0 -0.70" xyz="0 0 0"/>
      <geometry>
        <box size="0.043699999999999996 0.008 0.062000000000000006"/>
      </geometry>
      <material name="m3pro_dark_gray"/>
    </visual>
    <visual>
      <origin rpy="0.70 0 2.35" xyz="0 0 0"/>
      <geometry>
        <box size="0.043699999999999996 0.008 0.062000000000000006"/>
      </geometry>
      <material name="m3pro_dark_gray"/>
    </visual>
    <visual>
      <origin rpy="-0.70 0 -2.35" xyz="0 0 0"/>
      <geometry>
        <box size="0.043699999999999996 0.008 0.062000000000000006"/>
      </geometry>
      <material name="m3pro_dark_gray"/>
    </visual>
    <collision>
      <origin rpy="1.5707963267948966 0 0" xyz="0 0 0"/>
      <geometry>
        <cylinder length="0.038" radius="0.04"/>
      </geometry>
    </collision>
    <inertial>
      <origin rpy="1.5707963267948966 0 0" xyz="0 0 0"/>
      <mass value="0.35"/>
      <inertia ixx="0.00018211666666666663" ixy="0.0" ixz="0.0" iyy="0.00018211666666666663" iyz="0.0" izz="0.00028"/>
    </inertial>
  </link>
  <joint name="front_right_wheel_joint" type="continuous">
    <parent link="base_link"/>
    <child link="front_right_wheel_link"/>
    <origin rpy="0 0 0" xyz="0.145 -0.13 -0.01"/>
    <axis xyz="0 1 0"/>
    <limit effort="20.0" velocity="20.0"/>
    <dynamics damping="0.05" friction="0.02"/>
  </joint>
  <link name="rear_left_wheel_link">
    <visual>
      <origin rpy="1.5707963267948966 0 0" xyz="0 0 0"/>
      <geometry>
        <cylinder length="0.038" radius="0.04"/>
      </geometry>
      <material name="m3pro_black"/>
    </visual>
    <visual>
      <origin rpy="1.5707963267948966 0 0" xyz="0 0 0"/>
      <geometry>
        <cylinder length="0.041800000000000004" radius="0.018000000000000002"/>
      </geometry>
      <material name="m3pro_aluminum"/>
    </visual>
    <visual>
      <origin rpy="0.70 0 0.70" xyz="0 0 0"/>
      <geometry>
        <box size="0.043699999999999996 0.008 0.062000000000000006"/>
      </geometry>
      <material name="m3pro_dark_gray"/>
    </visual>
    <visual>
      <origin rpy="-0.70 0 -0.70" xyz="0 0 0"/>
      <geometry>
        <box size="0.043699999999999996 0.008 0.062000000000000006"/>
      </geometry>
      <material name="m3pro_dark_gray"/>
    </visual>
    <visual>
      <origin rpy="0.70 0 2.35" xyz="0 0 0"/>
      <geometry>
        <box size="0.043699999999999996 0.008 0.062000000000000006"/>
      </geometry>
      <material name="m3pro_dark_gray"/>
    </visual>
    <visual>
      <origin rpy="-0.70 0 -2.35" xyz="0 0 0"/>
      <geometry>
        <box size="0.043699999999999996 0.008 0.062000000000000006"/>
      </geometry>
      <material name="m3pro_dark_gray"/>
    </visual>
    <collision>
      <origin rpy="1.5707963267948966 0 0" xyz="0 0 0"/>
      <geometry>
        <cylinder length="0.038" radius="0.04"/>
      </geometry>
    </collision>
    <inertial>
      <origin rpy="1.5707963267948966 0 0" xyz="0 0 0"/>
      <mass value="0.35"/>
      <inertia ixx="0.00018211666666666663" ixy="0.0" ixz="0.0" iyy="0.00018211666666666663" iyz="0.0" izz="0.00028"/>
    </inertial>
  </link>
  <joint name="rear_left_wheel_joint" type="continuous">
    <parent link="base_link"/>
    <child link="rear_left_wheel_link"/>
    <origin rpy="0 0 0" xyz="-0.145 0.13 -0.01"/>
    <axis xyz="0 1 0"/>
    <limit effort="20.0" velocity="20.0"/>
    <dynamics damping="0.05" friction="0.02"/>
  </joint>
  <link name="rear_right_wheel_link">
    <visual>
      <origin rpy="1.5707963267948966 0 0" xyz="0 0 0"/>
      <geometry>
        <cylinder length="0.038" radius="0.04"/>
      </geometry>
      <material name="m3pro_black"/>
    </visual>
    <visual>
      <origin rpy="1.5707963267948966 0 0" xyz="0 0 0"/>
      <geometry>
        <cylinder length="0.041800000000000004" radius="0.018000000000000002"/>
      </geometry>
      <material name="m3pro_aluminum"/>
    </visual>
    <visual>
      <origin rpy="0.70 0 0.70" xyz="0 0 0"/>
      <geometry>
        <box size="0.043699999999999996 0.008 0.062000000000000006"/>
      </geometry>
      <material name="m3pro_dark_gray"/>
    </visual>
    <visual>
      <origin rpy="-0.70 0 -0.70" xyz="0 0 0"/>
      <geometry>
        <box size="0.043699999999999996 0.008 0.062000000000000006"/>
      </geometry>
      <material name="m3pro_dark_gray"/>
    </visual>
    <visual>
      <origin rpy="0.70 0 2.35" xyz="0 0 0"/>
      <geometry>
        <box size="0.043699999999999996 0.008 0.062000000000000006"/>
      </geometry>
      <material name="m3pro_dark_gray"/>
    </visual>
    <visual>
      <origin rpy="-0.70 0 -2.35" xyz="0 0 0"/>
      <geometry>
        <box size="0.043699999999999996 0.008 0.062000000000000006"/>
      </geometry>
      <material name="m3pro_dark_gray"/>
    </visual>
    <collision>
      <origin rpy="1.5707963267948966 0 0" xyz="0 0 0"/>
      <geometry>
        <cylinder length="0.038" radius="0.04"/>
      </geometry>
    </collision>
    <inertial>
      <origin rpy="1.5707963267948966 0 0" xyz="0 0 0"/>
      <mass value="0.35"/>
      <inertia ixx="0.00018211666666666663" ixy="0.0" ixz="0.0" iyy="0.00018211666666666663" iyz="0.0" izz="0.00028"/>
    </inertial>
  </link>
  <joint name="rear_right_wheel_joint" type="continuous">
    <parent link="base_link"/>
    <child link="rear_right_wheel_link"/>
    <origin rpy="0 0 0" xyz="-0.145 -0.13 -0.01"/>
    <axis xyz="0 1 0"/>
    <limit effort="20.0" velocity="20.0"/>
    <dynamics damping="0.05" friction="0.02"/>
  </joint>
  <link name="upper_deck_link">
    <visual>
      <origin rpy="0 0 0" xyz="0 0 0"/>
      <geometry>
        <box size="0.300 0.220 0.035"/>
      </geometry>
      <material name="m3pro_dark_gray"/>
    </visual>
    <collision>
      <origin rpy="0 0 0" xyz="0 0 0"/>
      <geometry>
        <box size="0.300 0.220 0.035"/>
      </geometry>
    </collision>
    <inertial>
      <origin rpy="0 0 0" xyz="0 0 0"/>
      <mass value="1.1"/>
      <inertia ixx="0.004548958333333333" ixy="0.0" ixz="0.0" iyy="0.008362291666666667" iyz="0.0" izz="0.012686666666666667"/>
    </inertial>
  </link>
  <joint name="upper_deck_joint" type="fixed">
    <parent link="base_link"/>
    <child link="upper_deck_link"/>
    <origin rpy="0 0 0" xyz="0 0 0.115"/>
  </joint>
  <link name="arm_base_link">
    <visual>
      <origin rpy="0 0 0" xyz="0 0 0.045"/>
      <geometry>
        <cylinder length="0.09" radius="0.055"/>
      </geometry>
      <material name="m3pro_dark_gray"/>
    </visual>
    <collision>
      <origin rpy="0 0 0" xyz="0 0 0.045"/>
      <geometry>
        <cylinder length="0.09" radius="0.055"/>
      </geometry>
    </collision>
    <inertial>
      <origin rpy="0 0 0" xyz="0 0 0.045"/>
      <mass value="0.7"/>
      <inertia ixx="0.001001875" ixy="0.0" ixz="0.0" iyy="0.001001875" iyz="0.0" izz="0.00105875"/>
    </inertial>
  </link>
  <link name="shoulder_link">
    <visual>
      <origin rpy="1.5707963267948966 0 0" xyz="0 0 0"/>
      <geometry>
        <cylinder length="0.095" radius="0.045"/>
      </geometry>
      <material name="m3pro_aluminum"/>
    </visual>
    <visual>
      <origin rpy="0 0 0" xyz="0 0 0.040"/>
      <geometry>
        <box size="0.075 0.060 0.080"/>
      </geometry>
      <material name="m3pro_blue"/>
    </visual>
    <collision>
      <origin rpy="0 0 0" xyz="0 0 0"/>
      <geometry>
        <box size="0.095 0.095 0.090"/>
      </geometry>
    </collision>
    <inertial>
      <origin rpy="0 0 0" xyz="0 0 0.020"/>
      <mass value="0.45"/>
      <inertia ixx="0.0006421875000000001" ixy="0.0" ixz="0.0" iyy="0.0006421875000000001" iyz="0.0" izz="0.000676875"/>
    </inertial>
  </link>
  <link name="upper_arm_link">
    <visual>
      <origin rpy="0 1.5707963267948966 0" xyz="0.105 0 0"/>
      <geometry>
        <cylinder length="0.21" radius="0.028"/>
      </geometry>
      <material name="m3pro_aluminum"/>
    </visual>
    <visual>
      <origin rpy="0 1.5707963267948966 0" xyz="0.105 0 0.030"/>
      <geometry>
        <cylinder length="0.1722" radius="0.018"/>
      </geometry>
      <material name="m3pro_blue"/>
    </visual>
    <collision>
      <origin rpy="0 0 0" xyz="0.105 0 0"/>
      <geometry>
        <box size="0.21 0.060 0.070"/>
      </geometry>
    </collision>
    <inertial>
      <origin rpy="0 0 0" xyz="0.105 0 0"/>
      <mass value="0.55"/>
      <inertia ixx="0.00038958333333333336" ixy="0.0" ixz="0.0" iyy="0.002245833333333333" iyz="0.0" izz="0.00218625"/>
    </inertial>
  </link>
  <link name="forearm_link">
    <visual>
      <origin rpy="0 1.5707963267948966 0" xyz="0.095 0 0"/>
      <geometry>
        <cylinder length="0.19" radius="0.024"/>
      </geometry>
      <material name="m3pro_aluminum"/>
    </visual>
    <visual>
      <origin rpy="0 1.5707963267948966 0" xyz="0.095 0 -0.026"/>
      <geometry>
        <cylinder length="0.15200000000000002" radius="0.015"/>
      </geometry>
      <material name="m3pro_blue"/>
    </visual>
    <collision>
      <origin rpy="0 0 0" xyz="0.095 0 0"/>
      <geometry>
        <box size="0.19 0.055 0.060"/>
      </geometry>
    </collision>
    <inertial>
      <origin rpy="0 0 0" xyz="0.095 0 0"/>
      <mass value="0.45"/>
      <inertia ixx="0.0002484375" ixy="0.0" ixz="0.0" iyy="0.0014887499999999998" iyz="0.0" izz="0.0014671875"/>
    </inertial>
  </link>
  <link name="wrist_1_link">
    <visual>
      <origin rpy="0 0 0" xyz="0 0 0.0425"/>
      <geometry>
        <cylinder length="0.085" radius="0.032"/>
      </geometry>
      <material name="m3pro_blue"/>
    </visual>
    <collision>
      <origin rpy="0 0 0" xyz="0 0 0.0425"/>
      <geometry>
        <cylinder length="0.085" radius="0.032"/>
      </geometry>
    </collision>
    <inertial>
      <origin rpy="0 0 0" xyz="0 0 0.0425"/>
      <mass value="0.2"/>
      <inertia ixx="0.0001716166666666667" ixy="0.0" ixz="0.0" iyy="0.0001716166666666667" iyz="0.0" izz="0.00010240000000000001"/>
    </inertial>
  </link>
  <link name="wrist_2_link">
    <visual>
      <origin rpy="1.5707963267948966 0 0" xyz="0 0 0"/>
      <geometry>
        <cylinder length="0.070" radius="0.030"/>
      </geometry>
      <material name="m3pro_blue"/>
    </visual>
    <collision>
      <origin rpy="0 0 0" xyz="0 0 0"/>
      <geometry>
        <box size="0.055 0.070 0.055"/>
      </geometry>
    </collision>
    <inertial>
      <origin rpy="0 0 0" xyz="0 0 0"/>
      <mass value="0.18"/>
      <inertia ixx="0.00011887500000000002" ixy="0.0" ixz="0.0" iyy="9.075e-05" iyz="0.0" izz="0.00011887500000000002"/>
    </inertial>
  </link>
  <link name="tool0">
    <visual>
      <origin rpy="0 1.5707963267948966 0" xyz="0.045 0 0"/>
      <geometry>
        <cylinder length="0.09" radius="0.020"/>
      </geometry>
      <material name="m3pro_black"/>
    </visual>
    <collision>
      <origin rpy="0 0 0" xyz="0.045 0 0"/>
      <geometry>
        <box size="0.09 0.045 0.045"/>
      </geometry>
    </collision>
    <inertial>
      <origin rpy="0 0 0" xyz="0.045 0 0"/>
      <mass value="0.12"/>
      <inertia ixx="4.0499999999999995e-05" ixy="0.0" ixz="0.0" iyy="0.00010124999999999998" iyz="0.0" izz="0.00010124999999999998"/>
    </inertial>
  </link>
  <joint name="arm_mount_joint" type="fixed">
    <parent link="upper_deck_link"/>
    <child link="arm_base_link"/>
    <origin rpy="0 0 0" xyz="0.035 0 0.030"/>
  </joint>
  <joint name="joint_1" type="revolute">
    <parent link="arm_base_link"/>
    <child link="shoulder_link"/>
    <origin rpy="0 0 0" xyz="0 0 0.09"/>
    <axis xyz="0 0 1"/>
    <limit effort="30.0" lower="-3.141592653589793" upper="3.141592653589793" velocity="1.5"/>
  </joint>
  <joint name="joint_2" type="revolute">
    <parent link="shoulder_link"/>
    <child link="upper_arm_link"/>
    <origin rpy="0 0 0" xyz="0 0 0.040"/>
    <axis xyz="0 1 0"/>
    <limit effort="30.0" lower="-1.5708" upper="1.5708" velocity="1.5"/>
  </joint>
  <joint name="joint_3" type="revolute">
    <parent link="upper_arm_link"/>
    <child link="forearm_link"/>
    <origin rpy="0 0 0" xyz="0.21 0 0"/>
    <axis xyz="0 1 0"/>
    <limit effort="25.0" lower="-2.3562" upper="2.3562" velocity="1.5"/>
  </joint>
  <joint name="joint_4" type="revolute">
    <parent link="forearm_link"/>
    <child link="wrist_1_link"/>
    <origin rpy="0 0 0" xyz="0.19 0 0"/>
    <axis xyz="1 0 0"/>
    <limit effort="15.0" lower="-3.141592653589793" upper="3.141592653589793" velocity="2.0"/>
  </joint>
  <joint name="joint_5" type="revolute">
    <parent link="wrist_1_link"/>
    <child link="wrist_2_link"/>
    <origin rpy="0 0 0" xyz="0 0 0.085"/>
    <axis xyz="0 1 0"/>
    <limit effort="15.0" lower="-1.5708" upper="1.5708" velocity="2.0"/>
  </joint>
  <joint name="joint_6" type="revolute">
    <parent link="wrist_2_link"/>
    <child link="tool0"/>
    <origin rpy="0 0 0" xyz="0 0 0.070"/>
    <axis xyz="1 0 0"/>
    <limit effort="10.0" lower="-3.141592653589793" upper="3.141592653589793" velocity="2.5"/>
  </joint>
  <link name="depth_camera_link">
    <visual>
      <origin rpy="0 0 0" xyz="0 0 0"/>
      <geometry>
        <box size="0.075 0.030 0.030"/>
      </geometry>
      <material name="m3pro_camera"/>
    </visual>
    <visual>
      <origin rpy="0 1.5707963267948966 0" xyz="0.041499999999999995 0.0275 0"/>
      <geometry>
        <cylinder length="0.008" radius="0.0096"/>
      </geometry>
      <material name="m3pro_lidar"/>
    </visual>
    <visual>
      <origin rpy="0 1.5707963267948966 0" xyz="0.041499999999999995 -0.0275 0"/>
      <geometry>
        <cylinder length="0.008" radius="0.0096"/>
      </geometry>
      <material name="m3pro_lidar"/>
    </visual>
    <visual>
      <origin rpy="0 0 0" xyz="0 0 -0.020999999999999998"/>
      <geometry>
        <box size="0.028499999999999998 0.0165 0.008400000000000001"/>
      </geometry>
      <material name="m3pro_dark_gray"/>
    </visual>
    <collision>
      <origin rpy="0 0 0" xyz="0 0 0"/>
      <geometry>
        <box size="0.075 0.030 0.030"/>
      </geometry>
    </collision>
    <inertial>
      <origin rpy="0 0 0" xyz="0 0 0"/>
      <mass value="0.08"/>
      <inertia ixx="1.2e-05" ixy="0.0" ixz="0.0" iyy="4.35e-05" iyz="0.0" izz="4.35e-05"/>
    </inertial>
  </link>
  <joint name="depth_camera_mount_joint" type="fixed">
    <parent link="tool0"/>
    <child link="depth_camera_link"/>
    <origin rpy="0 0 0" xyz="0.09 0 0.045"/>
  </joint>
  <link name="depth_camera_rgb_frame"/>
  <joint name="depth_camera_rgb_joint" type="fixed">
    <parent link="depth_camera_link"/>
    <child link="depth_camera_rgb_frame"/>
    <origin rpy="0 0 0" xyz="0 0.0275 0"/>
  </joint>
  <link name="depth_camera_depth_frame"/>
  <joint name="depth_camera_depth_joint" type="fixed">
    <parent link="depth_camera_link"/>
    <child link="depth_camera_depth_frame"/>
    <origin rpy="0 0 0" xyz="0 -0.0275 0"/>
  </joint>
  <link name="depth_camera_optical_frame"/>
  <joint name="depth_camera_optical_joint" type="fixed">
    <parent link="depth_camera_rgb_frame"/>
    <child link="depth_camera_optical_frame"/>
    <origin rpy="-1.5707963267948966 0 -1.5707963267948966" xyz="0 0 0"/>
  </joint>
  <link name="front_tof_lidar_link">
    <visual>
      <origin rpy="0 0 0" xyz="0 0 0.02"/>
      <geometry>
        <cylinder length="0.04" radius="0.035"/>
      </geometry>
      <material name="m3pro_lidar"/>
    </visual>
    <visual>
      <origin rpy="0 0 0" xyz="0 0 0.044"/>
      <geometry>
        <cylinder length="0.008" radius="0.0252"/>
      </geometry>
      <material name="m3pro_dark_gray"/>
    </visual>
    <visual>
      <origin rpy="0 0 0" xyz="0.0217 0 0.0248"/>
      <geometry>
        <box size="0.010 0.029750000000000002 0.011200000000000002"/>
      </geometry>
      <material name="m3pro_green"/>
    </visual>
    <collision>
      <origin rpy="0 0 0" xyz="0 0 0.02"/>
      <geometry>
        <cylinder length="0.04" radius="0.035"/>
      </geometry>
    </collision>
    <inertial>
      <origin rpy="0 0 0" xyz="0 0 0.02"/>
      <mass value="0.12"/>
      <inertia ixx="5.275000000000001e-05" ixy="0.0" ixz="0.0" iyy="5.275000000000001e-05" iyz="0.0" izz="7.350000000000001e-05"/>
    </inertial>
  </link>
  <joint name="front_tof_lidar_joint" type="fixed">
    <parent link="upper_deck_link"/>
    <child link="front_tof_lidar_link"/>
    <origin rpy="0 0 0" xyz="0.12 0.09 0.040"/>
  </joint>
  <link name="front_tof_lidar_scan_frame"/>
  <joint name="front_tof_lidar_scan_joint" type="fixed">
    <parent link="front_tof_lidar_link"/>
    <child link="front_tof_lidar_scan_frame"/>
    <origin rpy="0 0 0" xyz="0 0 0.04"/>
  </joint>
  <link name="rear_tof_lidar_link">
    <visual>
      <origin rpy="0 0 0" xyz="0 0 0.02"/>
      <geometry>
        <cylinder length="0.04" radius="0.035"/>
      </geometry>
      <material name="m3pro_lidar"/>
    </visual>
    <visual>
      <origin rpy="0 0 0" xyz="0 0 0.044"/>
      <geometry>
        <cylinder length="0.008" radius="0.0252"/>
      </geometry>
      <material name="m3pro_dark_gray"/>
    </visual>
    <visual>
      <origin rpy="0 0 0" xyz="0.0217 0 0.0248"/>
      <geometry>
        <box size="0.010 0.029750000000000002 0.011200000000000002"/>
      </geometry>
      <material name="m3pro_green"/>
    </visual>
    <collision>
      <origin rpy="0 0 0" xyz="0 0 0.02"/>
      <geometry>
        <cylinder length="0.04" radius="0.035"/>
      </geometry>
    </collision>
    <inertial>
      <origin rpy="0 0 0" xyz="0 0 0.02"/>
      <mass value="0.12"/>
      <inertia ixx="5.275000000000001e-05" ixy="0.0" ixz="0.0" iyy="5.275000000000001e-05" iyz="0.0" izz="7.350000000000001e-05"/>
    </inertial>
  </link>
  <joint name="rear_tof_lidar_joint" type="fixed">
    <parent link="upper_deck_link"/>
    <child link="rear_tof_lidar_link"/>
    <origin rpy="0 0 3.141592653589793" xyz="-0.12 -0.09 0.040"/>
  </joint>
  <link name="rear_tof_lidar_scan_frame"/>
  <joint name="rear_tof_lidar_scan_joint" type="fixed">
    <parent link="rear_tof_lidar_link"/>
    <child link="rear_tof_lidar_scan_frame"/>
    <origin rpy="0 0 0" xyz="0 0 0.04"/>
  </joint>
  <ros2_control name="RosmasterM3ProSystem" type="system">
    <hardware>
      <plugin>mock_components/GenericSystem</plugin>
    </hardware>
    <joint name="front_left_wheel_joint">
      <command_interface name="velocity"/>
      <state_interface name="position"/>
      <state_interface name="velocity"/>
    </joint>
    <joint name="front_right_wheel_joint">
      <command_interface name="velocity"/>
      <state_interface name="position"/>
      <state_interface name="velocity"/>
    </joint>
    <joint name="rear_left_wheel_joint">
      <command_interface name="velocity"/>
      <state_interface name="position"/>
      <state_interface name="velocity"/>
    </joint>
    <joint name="rear_right_wheel_joint">
      <command_interface name="velocity"/>
      <state_interface name="position"/>
      <state_interface name="velocity"/>
    </joint>
    <joint name="joint_1">
      <command_interface name="position"/>
      <state_interface name="position"/>
      <state_interface name="velocity"/>
    </joint>
    <joint name="joint_2">
      <command_interface name="position"/>
      <state_interface name="position"/>
      <state_interface name="velocity"/>
    </joint>
    <joint name="joint_3">
      <command_interface name="position"/>
      <state_interface name="position"/>
      <state_interface name="velocity"/>
    </joint>
    <joint name="joint_4">
      <command_interface name="position"/>
      <state_interface name="position"/>
      <state_interface name="velocity"/>
    </joint>
    <joint name="joint_5">
      <command_interface name="position"/>
      <state_interface name="position"/>
      <state_interface name="velocity"/>
    </joint>
    <joint name="joint_6">
      <command_interface name="position"/>
      <state_interface name="position"/>
      <state_interface name="velocity"/>
    </joint>
  </ros2_control>
</robot>
